INFO - [Nov 02 21:48:52] 127.0.0.1:65447 "AGENT CONNECT i1.ytimg.com:443 HTTP/1.
1" - -
INFO - [Nov 02 21:48:52] 127.0.0.1:65448 "FWD CONNECT gp3.googleusercontent.com:
443 HTTP/1.1" - -
INFO - [Nov 02 21:48:52] 127.0.0.1:65454 "FWD CONNECT plus.googleapis.com:443 HT
TP/1.1" - -
INFO - [Nov 02 21:48:53] 127.0.0.1:65447 "GAE GET https://i1.ytimg.com/i/DOyPdai
yeuf41fftvhpZsg/1.jpg HTTP/1.1" 404 775
INFO - [Nov 02 21:48:53] 127.0.0.1:65467 "AGENT CONNECT www.youtube.com:443 HTTP
/1.1" - -
INFO - [Nov 02 21:48:54] 127.0.0.1:65467 "FWD POST https://www.youtube.com/watch
_fragments_ajax?frags=guide&v=fZ_JOBCLF-I&spf=load HTTP/1.1" 200 1933
INFO - [Nov 02 21:48:54] 127.0.0.1:65473 "AGENT CONNECT i1.ytimg.com:443 HTTP/1.
1" - -
INFO - [Nov 02 21:48:54] 127.0.0.1:65474 "AGENT CONNECT i1.ytimg.com:443 HTTP/1.
1" - -
INFO - [Nov 02 21:48:54] 127.0.0.1:65475 "AGENT CONNECT i1.ytimg.com:443 HTTP/1.
1" - -
INFO - [Nov 02 21:48:54] 127.0.0.1:65476 "AGENT CONNECT i1.ytimg.com:443 HTTP/1.
1" - -
INFO - [Nov 02 21:48:54] 127.0.0.1:65480 "AGENT CONNECT i1.ytimg.com:443 HTTP/1.
1" - -
INFO - [Nov 02 21:48:54] 127.0.0.1:65481 "AGENT CONNECT i1.ytimg.com:443 HTTP/1.
1" - -
INFO - [Nov 02 21:48:54] 127.0.0.1:65483 "AGENT CONNECT www.youtube.com:443 HTTP
/1.1" - -
INFO - [Nov 02 21:48:54] 127.0.0.1:65473 "GAE GET https://i1.ytimg.com/li/tnHdj3
df7iM/default.jpg HTTP/1.1" 200 2743
INFO - [Nov 02 21:48:54] 127.0.0.1:65474 "GAE GET https://i1.ytimg.com/li/p-Rdqh
3z4Uc/default.jpg HTTP/1.1" 200 2863
INFO - [Nov 02 21:48:54] 127.0.0.1:65475 "GAE GET https://i1.ytimg.com/li/7Dr1BK
wqctY/default.jpg HTTP/1.1" 200 3934
INFO - [Nov 02 21:48:54] 127.0.0.1:65509 "AGENT CONNECT i1.ytimg.com:443 HTTP/1.
1" - -
INFO - [Nov 02 21:48:54] 127.0.0.1:65510 "AGENT CONNECT i1.ytimg.com:443 HTTP/1.
1" - -
INFO - [Nov 02 21:48:54] 127.0.0.1:65511 "AGENT CONNECT i1.ytimg.com:443 HTTP/1.
1" - -
INFO - [Nov 02 21:48:54] 127.0.0.1:65480 "GAE GET https://i1.ytimg.com/i/GjylN-4
QCpn8XJ1uY-UOgA/1.jpg HTTP/1.1" 200 2368
INFO - [Nov 02 21:48:54] 127.0.0.1:65481 "GAE GET https://i1.ytimg.com/i/qyku6Ko
fy1nV86yh9R8n8A/1.jpg HTTP/1.1" 200 5478
INFO - [Nov 02 21:48:54] 127.0.0.1:65476 "GAE GET https://i1.ytimg.com/li/hfZhJd
hTqX8/default.jpg HTTP/1.1" 200 2510
INFO - [Nov 02 21:48:55] 127.0.0.1:65483 "FWD GET https://www.youtube.com/gen_20
4?a=context-rendered-closed&context-type=home HTTP/1.1" 204 0
INFO - [Nov 02 21:48:55] 127.0.0.1:65511 "GAE GET https://i1.ytimg.com/i/oLrcjPV
5PbUrUyXq5mjc_A/1.jpg HTTP/1.1" 200 2616
INFO - [Nov 02 21:48:55] 127.0.0.1:65510 "GAE GET https://i1.ytimg.com/i/HX5-wIW
TaClDu6uTKXKItg/1.jpg HTTP/1.1" 200 8836
INFO - [Nov 02 21:48:55] 127.0.0.1:65509 "GAE GET https://i1.ytimg.com/i/huLeaTG
Rcfzo0UjL-2qSbQ/1.jpg HTTP/1.1" 200 4005
INFO - [Nov 02 21:48:59] 127.0.0.1:65530 "AGENT CONNECT s.youtube.com:443 HTTP/1
.1" - -
----------------------------------------
Exception happened during processing of request from ('127.0.0.1', 65530)
Traceback (most recent call last):
  File "D:\WEB\goagent\local\python27.zip\SocketServer.py", line 593, in process
_request_thread
  File "proxy.py", line 1712, in finish_request
  File "D:\WEB\goagent\local\python27.zip\SocketServer.py", line 649, in __init_
_
  File "D:\WEB\goagent\local\python27.zip\BaseHTTPServer.py", line 340, in handl
e
  File "D:\WEB\goagent\local\python27.zip\BaseHTTPServer.py", line 328, in handl
e_one_request
  File "proxy.py", line 2086, in do_CONNECT
  File "proxy.py", line 2174, in do_CONNECT_AGENT
  File "proxy.py", line 1889, in do_METHOD
  File "proxy.py", line 1901, in do_METHOD_FWD
  File "proxy.py", line 1279, in request
  File "proxy.py", line 1069, in create_ssl_connection
  File "proxy.py", line 891, in dns_resolve
  File "D:\WEB\goagent\local\python27.zip\gevent\socket.py", line 617, in gethos
tbyname_ex
gaierror: [Errno 11004] getaddrinfo failed
----------------------------------------
INFO - [Nov 02 21:49:01] 127.0.0.1:65532 "AGENT CONNECT s.youtube.com:443 HTTP/1
.1" - -
INFO - [Nov 02 21:49:02] 127.0.0.1:65533 "AGENT CONNECT s.youtube.com:443 HTTP/1
.1" - -
----------------------------------------
Exception happened during processing of request from ('127.0.0.1', 65532)
Traceback (most recent call last):
  File "D:\WEB\goagent\local\python27.zip\SocketServer.py", line 593, in process
_request_thread
  File "proxy.py", line 1712, in finish_request
  File "D:\WEB\goagent\local\python27.zip\SocketServer.py", line 649, in __init_
_
  File "D:\WEB\goagent\local\python27.zip\BaseHTTPServer.py", line 340, in handl
e
  File "D:\WEB\goagent\local\python27.zip\BaseHTTPServer.py", line 328, in handl
e_one_request
  File "proxy.py", line 2086, in do_CONNECT
  File "proxy.py", line 2174, in do_CONNECT_AGENT
  File "proxy.py", line 1889, in do_METHOD
  File "proxy.py", line 1901, in do_METHOD_FWD
  File "proxy.py", line 1279, in request
  File "proxy.py", line 1069, in create_ssl_connection
  File "proxy.py", line 891, in dns_resolve
  File "D:\WEB\goagent\local\python27.zip\gevent\socket.py", line 617, in gethos
tbyname_ex
gaierror: [Errno 11004] getaddrinfo failed
----------------------------------------
----------------------------------------
Exception happened during processing of request from ('127.0.0.1', 65533)
Traceback (most recent call last):
  File "D:\WEB\goagent\local\python27.zip\SocketServer.py", line 593, in process
_request_thread
  File "proxy.py", line 1712, in finish_request
  File "D:\WEB\goagent\local\python27.zip\SocketServer.py", line 649, in __init_
_
  File "D:\WEB\goagent\local\python27.zip\BaseHTTPServer.py", line 340, in handl
e
  File "D:\WEB\goagent\local\python27.zip\BaseHTTPServer.py", line 328, in handl
e_one_request
  File "proxy.py", line 2086, in do_CONNECT
  File "proxy.py", line 2174, in do_CONNECT_AGENT
  File "proxy.py", line 1889, in do_METHOD
  File "proxy.py", line 1901, in do_METHOD_FWD
  File "proxy.py", line 1279, in request
  File "proxy.py", line 1069, in create_ssl_connection
  File "proxy.py", line 891, in dns_resolve
  File "D:\WEB\goagent\local\python27.zip\gevent\socket.py", line 617, in gethos
tbyname_ex
gaierror: [Errno 11004] getaddrinfo failed
----------------------------------------
INFO - [Nov 02 21:49:04] 127.0.0.1:49161 "AGENT CONNECT s.youtube.com:443 HTTP/1
.1" - -
----------------------------------------
Exception happened during processing of request from ('127.0.0.1', 49161)
Traceback (most recent call last):
  File "D:\WEB\goagent\local\python27.zip\SocketServer.py", line 593, in process
_request_thread
  File "proxy.py", line 1712, in finish_request
  File "D:\WEB\goagent\local\python27.zip\SocketServer.py", line 649, in __init_
_
  File "D:\WEB\goagent\local\python27.zip\BaseHTTPServer.py", line 340, in handl
e
  File "D:\WEB\goagent\local\python27.zip\BaseHTTPServer.py", line 328, in handl
e_one_request
  File "proxy.py", line 2086, in do_CONNECT
  File "proxy.py", line 2174, in do_CONNECT_AGENT
  File "proxy.py", line 1889, in do_METHOD
  File "proxy.py", line 1901, in do_METHOD_FWD
  File "proxy.py", line 1279, in request
  File "proxy.py", line 1069, in create_ssl_connection
  File "proxy.py", line 891, in dns_resolve
  File "D:\WEB\goagent\local\python27.zip\gevent\socket.py", line 617, in gethos
tbyname_ex
gaierror: [Errno 11004] getaddrinfo failed
----------------------------------------
INFO - [Nov 02 21:49:07] 127.0.0.1:49168 "AGENT CONNECT www.youtube.com:443 HTTP
/1.1" - -
INFO - [Nov 02 21:49:08] 127.0.0.1:49168 "FWD GET https://www.youtube.com/live_c
omments?action_get_comments=1&video_id=fZ_JOBCLF-I&lt=1383400099&format=html&nnc
=0&pd=15000&rc=0&dst=0&lch=760&ps=-1&pvd=181&pct=0 HTTP/1.1" 200 225
INFO - [Nov 02 21:49:09] 127.0.0.1:49182 "AGENT CONNECT s.youtube.com:443 HTTP/1
.1" - -
----------------------------------------
Exception happened during processing of request from ('127.0.0.1', 49182)
Traceback (most recent call last):
  File "D:\WEB\goagent\local\python27.zip\SocketServer.py", line 593, in process
_request_thread
  File "proxy.py", line 1712, in finish_request
  File "D:\WEB\goagent\local\python27.zip\SocketServer.py", line 649, in __init_
_
  File "D:\WEB\goagent\local\python27.zip\BaseHTTPServer.py", line 340, in handl
e
  File "D:\WEB\goagent\local\python27.zip\BaseHTTPServer.py", line 328, in handl
e_one_request
  File "proxy.py", line 2086, in do_CONNECT
  File "proxy.py", line 2174, in do_CONNECT_AGENT
  File "proxy.py", line 1889, in do_METHOD
  File "proxy.py", line 1901, in do_METHOD_FWD
  File "proxy.py", line 1279, in request
  File "proxy.py", line 1069, in create_ssl_connection
  File "proxy.py", line 891, in dns_resolve
  File "D:\WEB\goagent\local\python27.zip\gevent\socket.py", line 617, in gethos
tbyname_ex
gaierror: [Errno 11004] getaddrinfo failed
----------------------------------------
INFO - [Nov 02 21:49:19] 127.0.0.1:49201 "AGENT CONNECT s.youtube.com:443 HTTP/1
.1" - -
INFO - [Nov 02 21:49:25] 127.0.0.1:49202 "AGENT CONNECT s.youtube.com:443 HTTP/1
.1" - -
----------------------------------------
Exception happened during processing of request from ('127.0.0.1', 49201)
Traceback (most recent call last):
  File "D:\WEB\goagent\local\python27.zip\SocketServer.py", line 593, in process
_request_thread
  File "proxy.py", line 1712, in finish_request
  File "D:\WEB\goagent\local\python27.zip\SocketServer.py", line 649, in __init_
_
  File "D:\WEB\goagent\local\python27.zip\BaseHTTPServer.py", line 340, in handl
e
  File "D:\WEB\goagent\local\python27.zip\BaseHTTPServer.py", line 328, in handl
e_one_request
  File "proxy.py", line 2086, in do_CONNECT
  File "proxy.py", line 2174, in do_CONNECT_AGENT
  File "proxy.py", line 1889, in do_METHOD
  File "proxy.py", line 1901, in do_METHOD_FWD
  File "proxy.py", line 1279, in request
  File "proxy.py", line 1069, in create_ssl_connection
  File "proxy.py", line 891, in dns_resolve
  File "D:\WEB\goagent\local\python27.zip\gevent\socket.py", line 617, in gethos
tbyname_ex
gaierror: [Errno 11004] getaddrinfo failed
----------------------------------------
----------------------------------------
Exception happened during processing of request from ('127.0.0.1', 49202)
Traceback (most recent call last):
  File "D:\WEB\goagent\local\python27.zip\SocketServer.py", line 593, in process
_request_thread
  File "proxy.py", line 1712, in finish_request
  File "D:\WEB\goagent\local\python27.zip\SocketServer.py", line 649, in __init_
_
  File "D:\WEB\goagent\local\python27.zip\BaseHTTPServer.py", line 340, in handl
e
  File "D:\WEB\goagent\local\python27.zip\BaseHTTPServer.py", line 328, in handl
e_one_request
  File "proxy.py", line 2086, in do_CONNECT
  File "proxy.py", line 2174, in do_CONNECT_AGENT
  File "proxy.py", line 1889, in do_METHOD
  File "proxy.py", line 1901, in do_METHOD_FWD
  File "proxy.py", line 1279, in request
  File "proxy.py", line 1069, in create_ssl_connection
  File "proxy.py", line 891, in dns_resolve
  File "D:\WEB\goagent\local\python27.zip\gevent\socket.py", line 617, in gethos
tbyname_ex
gaierror: [Errno 11004] getaddrinfo failed
----------------------------------------
INFO - [Nov 02 21:49:25] 127.0.0.1:49215 "AGENT CONNECT s.youtube.com:443 HTTP/1
.1" - -
INFO - [Nov 02 21:49:25] 127.0.0.1:49216 "AGENT CONNECT s.youtube.com:443 HTTP/1
.1" - -
----------------------------------------
Exception happened during processing of request from ('127.0.0.1', 49215)
Traceback (most recent call last):
  File "D:\WEB\goagent\local\python27.zip\SocketServer.py", line 593, in process
_request_thread
  File "proxy.py", line 1712, in finish_request
  File "D:\WEB\goagent\local\python27.zip\SocketServer.py", line 649, in __init_
_
  File "D:\WEB\goagent\local\python27.zip\BaseHTTPServer.py", line 340, in handl
e
  File "D:\WEB\goagent\local\python27.zip\BaseHTTPServer.py", line 328, in handl
e_one_request
  File "proxy.py", line 2086, in do_CONNECT
  File "proxy.py", line 2174, in do_CONNECT_AGENT
  File "proxy.py", line 1889, in do_METHOD
  File "proxy.py", line 1901, in do_METHOD_FWD
  File "proxy.py", line 1279, in request
  File "proxy.py", line 1069, in create_ssl_connection
  File "proxy.py", line 891, in dns_resolve
  File "D:\WEB\goagent\local\python27.zip\gevent\socket.py", line 617, in gethos
tbyname_ex
gaierror: [Errno 11004] getaddrinfo failed
----------------------------------------
----------------------------------------
Exception happened during processing of request from ('127.0.0.1', 49216)
Traceback (most recent call last):
  File "D:\WEB\goagent\local\python27.zip\SocketServer.py", line 593, in process
_request_thread
  File "proxy.py", line 1712, in finish_request
  File "D:\WEB\goagent\local\python27.zip\SocketServer.py", line 649, in __init_
_
  File "D:\WEB\goagent\local\python27.zip\BaseHTTPServer.py", line 340, in handl
e
  File "D:\WEB\goagent\local\python27.zip\BaseHTTPServer.py", line 328, in handl
e_one_request
  File "proxy.py", line 2086, in do_CONNECT
  File "proxy.py", line 2174, in do_CONNECT_AGENT
  File "proxy.py", line 1889, in do_METHOD
  File "proxy.py", line 1901, in do_METHOD_FWD
  File "proxy.py", line 1279, in request
  File "proxy.py", line 1069, in create_ssl_connection
  File "proxy.py", line 891, in dns_resolve
  File "D:\WEB\goagent\local\python27.zip\gevent\socket.py", line 617, in gethos
tbyname_ex
gaierror: [Errno 11004] getaddrinfo failed
----------------------------------------
INFO - [Nov 02 21:49:27] 127.0.0.1:49219 "AGENT CONNECT lp-push-server-910.lastp
ass.com:443 HTTP/1.1" - -
INFO - [Nov 02 21:49:27] 127.0.0.1:49218 "AGENT CONNECT i1.ytimg.com:443 HTTP/1.
1" - -
INFO - [Nov 02 21:49:28] 127.0.0.1:49219 "GAE GET https://lp-push-server-910.las
tpass.com/ws/6b44863ec48ce3bf8a96b927c7ce95f8e21fcace9069a3b91b9a23885a076424 HT
TP/1.1" 400 0
INFO - [Nov 02 21:49:28] 127.0.0.1:49218 "GAE GET https://i1.ytimg.com/sb/fZ_JOB
CLF-I/storyboard3_L2/M2.jpg?sigh=yJEMvC4c40JNKnvSt9FxoODzaiY HTTP/1.1" 200 67381

INFO - [Nov 02 21:49:38] 127.0.0.1:49247 "AGENT CONNECT www.youtube.com:443 HTTP
/1.1" - -
WARNING - [Nov 02 21:49:54] create_ssl_connection to [('173.194.72.102', 443), (
'173.194.72.139', 443)] return timeout('timed out',), try again.
INFO - [Nov 02 21:49:55] 127.0.0.1:49247 "FWD GET https://www.youtube.com/live_c
omments?action_get_comments=1&video_id=fZ_JOBCLF-I&lt=1383400099&format=html&nnc
=0&pd=30000&rc=1&dst=0&lch=760&ps=-1&pvd=181&pct=0 HTTP/1.1" 200 2015
