WARNING - [Jan 25 15:25:48] Load Crypto.Cipher.ARC4 Failed, Use Pure Python Instead.
INFO - [Jan 25 15:25:55] resolve common.IPLIST_MAP names=['google_cn', 'google_hk', 'google_ipv6', 'talk.google.com', 'talk.l.google.com', 'talkx.l.google.com'] to iplist
Unhandled exception in thread started by <function do_remote_resolve at 0x10c6fab18>
------------------------------------------------------
GoAgent Version    : 3.1.5 (python/2.7.5 pyopenssl/0.13)
Listen Address     : 127.0.0.1:8087
GAE Mode           : https
GAE Profile        : ipv4
GAE APPID          : firemyapp01
Pac Server         : http://127.0.0.1:8086/proxy.pac
Pac File           : file:///Users/leopold/Downloads/goagent-goagent-b767d1f/local/proxy.pac
------------------------------------------------------
Traceback (most recent call last):
Unhandled exception in thread started by <function do_remote_resolve at 0x10c6fab18>
Traceback (most recent call last):
  File "proxy.py", line 1420, in do_remote_resolve
Unhandled exception in thread started by <function do_remote_resolve at 0x10c6fab18>
Traceback (most recent call last):
  File "proxy.py", line 1420, in do_remote_resolve
Unhandled exception in thread started by <function do_remote_resolve at 0x10c6fab18>  File "proxy.py", line 1420, in do_remote_resolve
    queue.put((host, dnsservers, dns_remote_resolve(host, dnsservers, self.DNS_BLACKLIST, timeout=2)))
  File "proxy.py", line 781, in dns_remote_resolve
    except gevent.timeout.Timeout as e:
    queue.put((host, dnsservers, dns_remote_resolve(host, dnsservers, self.DNS_BLACKLIST, timeout=2)))

Traceback (most recent call last):
  File "proxy.py", line 1420, in do_remote_resolve
AttributeError: 'NoneType' object has no attribute 'timeout'Unhandled exception in thread started by <function do_remote_resolve at 0x10c6fab18>
Traceback (most recent call last):
  File "proxy.py", line 1420, in do_remote_resolve
      File "proxy.py", line 781, in dns_remote_resolve
    except gevent.timeout.Timeout as e:
AttributeError: 'NoneType' object has no attribute 'timeout'Unhandled exception in thread started by <function do_remote_resolve at 0x10c6fab18>
Traceback (most recent call last):
  File "proxy.py", line 1420, in do_remote_resolve
Unhandled exception in thread started by <function do_remote_resolve at 0x10c6fab18>
Traceback (most recent call last):
queue.put((host, dnsservers, dns_remote_resolve(host, dnsservers, self.DNS_BLACKLIST, timeout=2)))
    

    queue.put((host, dnsservers, dns_remote_resolve(host, dnsservers, self.DNS_BLACKLIST, timeout=2)))
  File "proxy.py", line 781, in dns_remote_resolve
    except gevent.timeout.Timeout as e:
AttributeError: 'NoneType' object has no attribute 'timeout'  File "proxy.py", line 781, in dns_remote_resolve
    except gevent.timeout.Timeout as e:
Unhandled exception in thread started by <function do_remote_resolve at 0x10c6fab18>
Traceback (most recent call last):
  File "proxy.py", line 1420, in do_remote_resolve

Unhandled exception in thread started by <function do_remote_resolve at 0x10c6fab18>
Traceback (most recent call last):
  File "proxy.py", line 1420, in do_remote_resolve
Unhandled exception in thread started by <function do_remote_resolve at 0x10c6fab18>
Traceback (most recent call last):
  File "proxy.py", line 1420, in do_remote_resolve
  File "proxy.py", line 1420, in do_remote_resolve
Unhandled exception in thread started by <function do_remote_resolve at 0x10c6fab18>
Traceback (most recent call last):
  File "proxy.py", line 1420, in do_remote_resolve
AttributeError: 'NoneType' object has no attribute 'timeout'    queue.put((host, dnsservers, dns_remote_resolve(host, dnsservers, self.DNS_BLACKLIST, timeout=2)))
    queue.put((host, dnsservers, dns_remote_resolve(host, dnsservers, self.DNS_BLACKLIST, timeout=2)))
    queue.put((host, dnsservers, dns_remote_resolve(host, dnsservers, self.DNS_BLACKLIST, timeout=2)))
queue.put((host, dnsservers, dns_remote_resolve(host, dnsservers, self.DNS_BLACKLIST, timeout=2)))
  File "proxy.py", line 781, in dns_remote_resolve
    queue.put((host, dnsservers, dns_remote_resolve(host, dnsservers, self.DNS_BLACKLIST, timeout=2)))
Unhandled exception in thread started by <function do_remote_resolve at 0x10c6fab18>
Traceback (most recent call last):
  File "proxy.py", line 1420, in do_remote_resolve
Unhandled exception in thread started by <function do_remote_resolve at 0x10c6fab18>
Traceback (most recent call last):
  File "proxy.py", line 1420, in do_remote_resolve
Unhandled exception in thread started by <function do_remote_resolve at 0x10c6fab18>
Traceback (most recent call last):
  File "proxy.py", line 1420, in do_remote_resolve
    queue.put((host, dnsservers, dns_remote_resolve(host, dnsservers, self.DNS_BLACKLIST, timeout=2)))
    queue.put((host, dnsservers, dns_remote_resolve(host, dnsservers, self.DNS_BLACKLIST, timeout=2)))

  File "proxy.py", line 781, in dns_remote_resolve
    queue.put((host, dnsservers, dns_remote_resolve(host, dnsservers, self.DNS_BLACKLIST, timeout=2)))
Unhandled exception in thread started by <function do_remote_resolve at 0x10c6fab18>
Traceback (most recent call last):
  File "proxy.py", line 1420, in do_remote_resolve
    queue.put((host, dnsservers, dns_remote_resolve(host, dnsservers, self.DNS_BLACKLIST, timeout=2)))
  File "proxy.py", line 781, in dns_remote_resolve
    except gevent.timeout.Timeout as e:
  File "proxy.py", line 781, in dns_remote_resolve
    except gevent.timeout.Timeout as e:
  File "proxy.py", line 781, in dns_remote_resolve
  File "proxy.py", line 781, in dns_remote_resolve
    except gevent.timeout.Timeout as e:
Unhandled exception in thread started by <function do_remote_resolve at 0x10c6fab18>
Traceback (most recent call last):
  File "proxy.py", line 781, in dns_remote_resolve
  File "proxy.py", line 781, in dns_remote_resolve
    except gevent.timeout.Timeout as e:
    queue.put((host, dnsservers, dns_remote_resolve(host, dnsservers, self.DNS_BLACKLIST, timeout=2)))
  File "proxy.py", line 781, in dns_remote_resolve
    except gevent.timeout.Timeout as e:
    except gevent.timeout.Timeout as e:
    queue.put((host, dnsservers, dns_remote_resolve(host, dnsservers, self.DNS_BLACKLIST, timeout=2)))
  File "proxy.py", line 1420, in do_remote_resolve
    queue.put((host, dnsservers, dns_remote_resolve(host, dnsservers, self.DNS_BLACKLIST, timeout=2)))
Unhandled exception in thread started by <function do_remote_resolve at 0x10c6fab18>
Traceback (most recent call last):
  File "proxy.py", line 1420, in do_remote_resolve
  File "proxy.py", line 781, in dns_remote_resolve
AttributeError: 'NoneType' object has no attribute 'timeout'    except gevent.timeout.Timeout as e:
Unhandled exception in thread started by <function do_remote_resolve at 0x10c6fab18>
Traceback (most recent call last):
  File "proxy.py", line 1420, in do_remote_resolve
Unhandled exception in thread started by <function do_remote_resolve at 0x10c6fab18>
Traceback (most recent call last):
  File "proxy.py", line 1420, in do_remote_resolve
AttributeError:         except gevent.timeout.Timeout as e:

AttributeError: AttributeError  File "proxy.py", line 781, in dns_remote_resolve
    except gevent.timeout.Timeout as e:
    except gevent.timeout.Timeout as e:
    queue.put((host, dnsservers, dns_remote_resolve(host, dnsservers, self.DNS_BLACKLIST, timeout=2)))
'NoneType' object has no attribute 'timeout'    except gevent.timeout.Timeout as e:
AttributeError: 'NoneType' object has no attribute 'timeout'
    queue.put((host, dnsservers, dns_remote_resolve(host, dnsservers, self.DNS_BLACKLIST, timeout=2)))
AttributeErrorAttributeError: AttributeError
queue.put((host, dnsservers, dns_remote_resolve(host, dnsservers, self.DNS_BLACKLIST, timeout=2)))
AttributeError: 'NoneType' object has no attribute 'timeout'AttributeError
: Unhandled exception in thread started by <function do_remote_resolve at 0x10c6fab18>
Traceback (most recent call last):
  File "proxy.py", line 1420, in do_remote_resolve
'NoneType' object has no attribute 'timeout'  File "proxy.py", line 781, in dns_remote_resolve
  File "proxy.py", line 781, in dns_remote_resolve
    except gevent.timeout.Timeout as e:
AttributeError:   File "proxy.py", line 781, in dns_remote_resolve
    except gevent.timeout.Timeout as e:
'NoneType' object has no attribute 'timeout':     queue.put((host, dnsservers, dns_remote_resolve(host, dnsservers, self.DNS_BLACKLIST, timeout=2)))

AttributeError: 'NoneType' object has no attribute 'timeout': 'NoneType' object has no attribute 'timeout'AttributeError: 'NoneType' object has no attribute 'timeout'
    except gevent.timeout.Timeout as e:
  File "proxy.py", line 781, in dns_remote_resolve
    except gevent.timeout.Timeout as e:
AttributeError: 'NoneType' object has no attribute 'timeout': 
'NoneType' object has no attribute 'timeout''NoneType' object has no attribute 'timeout'

'NoneType' object has no attribute 'timeout'  File "proxy.py", line 781, in dns_remote_resolve
    except gevent.timeout.Timeout as e:

'NoneType' object has no attribute 'timeout'

AttributeError: 'NoneType' object has no attribute 'timeout'


AttributeError: 'NoneType' object has no attribute 'timeout'
WARNING - [Jan 25 15:25:57] resolve remote timeout, continue
ERROR - [Jan 25 15:25:57] resolve google_hk host return empty! please retry!
Traceback (most recent call last):
  File "/System/Library/Frameworks/Python.framework/Versions/2.7/lib/python2.7/SocketServer.py", line 593, in process_request_thread
    self.finish_request(request, client_address)
  File "proxy.py", line 1828, in finish_request
    self.RequestHandlerClass(request, client_address, self)
  File "/System/Library/Frameworks/Python.framework/Versions/2.7/lib/python2.7/SocketServer.py", line 647, in __init__
    self.setup()
  File "proxy.py", line 1916, in setup
    self.first_run()
  File "proxy.py", line 1901, in first_run
    common.resolve_iplist()
  File "proxy.py", line 1452, in resolve_iplist
    sys.exit(-1)
SystemExit: -1
INFO - [Jan 25 15:25:57] resolve common.IPLIST_MAP names=['google_cn', 'google_hk', 'google_ipv6', 'talk.google.com', 'talk.l.google.com', 'talkx.l.google.com'] to iplist
Unhandled exception in thread started by <function do_remote_resolve at 0x10c6fab18>
----------------------------------------
Exception happened during processing of request from ('127.0.0.1', 65019)
----------------------------------------
Traceback (most recent call last):
  File "proxy.py", line 1420, in do_remote_resolve
    queue.put((host, dnsservers, dns_remote_resolve(host, dnsservers, self.DNS_BLACKLIST, timeout=2)))
Unhandled exception in thread started by <function do_remote_resolve at 0x10c6fab18>
Traceback (most recent call last):
  File "proxy.py", line 1420, in do_remote_resolve
Unhandled exception in thread started by <function do_remote_resolve at 0x10c6fab18>
Traceback (most recent call last):
  File "proxy.py", line 1420, in do_remote_resolve
  File "proxy.py", line 781, in dns_remote_resolve
    except gevent.timeout.Timeout as e:
Unhandled exception in thread started by <function do_remote_resolve at 0x10c6fab18>
Traceback (most recent call last):
  File "proxy.py", line 1420, in do_remote_resolve
    queue.put((host, dnsservers, dns_remote_resolve(host, dnsservers, self.DNS_BLACKLIST, timeout=2)))
Unhandled exception in thread started by <function do_remote_resolve at 0x10c6fab18>
Traceback (most recent call last):
  File "proxy.py", line 1420, in do_remote_resolve
    queue.put((host, dnsservers, dns_remote_resolve(host, dnsservers, self.DNS_BLACKLIST, timeout=2)))
Unhandled exception in thread started by <function do_remote_resolve at 0x10c6fab18>
Traceback (most recent call last):
  File "proxy.py", line 1420, in do_remote_resolve
  File "proxy.py", line 781, in dns_remote_resolve
Unhandled exception in thread started by <function do_remote_resolve at 0x10c6fab18>
Traceback (most recent call last):
  File "proxy.py", line 1420, in do_remote_resolve
    queue.put((host, dnsservers, dns_remote_resolve(host, dnsservers, self.DNS_BLACKLIST, timeout=2)))
Unhandled exception in thread started by <function do_remote_resolve at 0x10c6fab18>
Traceback (most recent call last):
  File "proxy.py", line 1420, in do_remote_resolve
Unhandled exception in thread started by <function do_remote_resolve at 0x10c6fab18>
Traceback (most recent call last):
    except gevent.timeout.Timeout as e:
Unhandled exception in thread started by <function do_remote_resolve at 0x10c6fab18>
Traceback (most recent call last):
    Unhandled exception in thread started by <function do_remote_resolve at 0x10c6fab18>
Traceback (most recent call last):
  File "proxy.py", line 1420, in do_remote_resolve
  File "proxy.py", line 781, in dns_remote_resolve
    except gevent.timeout.Timeout as e:
  File "proxy.py", line 1420, in do_remote_resolve
Unhandled exception in thread started by <function do_remote_resolve at 0x10c6fab18>
Traceback (most recent call last):
  File "proxy.py", line 1420, in do_remote_resolve
    queue.put((host, dnsservers, dns_remote_resolve(host, dnsservers, self.DNS_BLACKLIST, timeout=2)))
AttributeError    queue.put((host, dnsservers, dns_remote_resolve(host, dnsservers, self.DNS_BLACKLIST, timeout=2)))
    queue.put((host, dnsservers, dns_remote_resolve(host, dnsservers, self.DNS_BLACKLIST, timeout=2)))
  File "proxy.py", line 781, in dns_remote_resolve
    except gevent.timeout.Timeout as e:
  File "proxy.py", line 781, in dns_remote_resolve
:   File "proxy.py", line 1420, in do_remote_resolve
'NoneType' object has no attribute 'timeout'
  File "proxy.py", line 781, in dns_remote_resolve
Unhandled exception in thread started by <function do_remote_resolve at 0x10c6fab18>
Traceback (most recent call last):
  File "proxy.py", line 1420, in do_remote_resolve
AttributeError: Unhandled exception in thread started by <function do_remote_resolve at 0x10c6fab18>
Traceback (most recent call last):
  File "proxy.py", line 1420, in do_remote_resolve
Unhandled exception in thread started by <function do_remote_resolve at 0x10c6fab18>
Traceback (most recent call last):
    queue.put((host, dnsservers, dns_remote_resolve(host, dnsservers, self.DNS_BLACKLIST, timeout=2)))
    queue.put((host, dnsservers, dns_remote_resolve(host, dnsservers, self.DNS_BLACKLIST, timeout=2)))
  File "proxy.py", line 781, in dns_remote_resolve
    except gevent.timeout.Timeout as e:
AttributeError    queue.put((host, dnsservers, dns_remote_resolve(host, dnsservers, self.DNS_BLACKLIST, timeout=2)))
Unhandled exception in thread started by <function do_remote_resolve at 0x10c6fab18>
Traceback (most recent call last):
  File "proxy.py", line 1420, in do_remote_resolve
    queue.put((host, dnsservers, dns_remote_resolve(host, dnsservers, self.DNS_BLACKLIST, timeout=2)))
  File "proxy.py", line 1420, in do_remote_resolve
  File "proxy.py", line 781, in dns_remote_resolve
    except gevent.timeout.Timeout as e:
    queue.put((host, dnsservers, dns_remote_resolve(host, dnsservers, self.DNS_BLACKLIST, timeout=2)))
Unhandled exception in thread started by <function do_remote_resolve at 0x10c6fab18>
Traceback (most recent call last):
  File "proxy.py", line 1420, in do_remote_resolve
  File "proxy.py", line 781, in dns_remote_resolve
    except gevent.timeout.Timeout as e:
AttributeError:     queue.put((host, dnsservers, dns_remote_resolve(host, dnsservers, self.DNS_BLACKLIST, timeout=2)))
AttributeError  File "proxy.py", line 781, in dns_remote_resolve
    except gevent.timeout.Timeout as e:
queue.put((host, dnsservers, dns_remote_resolve(host, dnsservers, self.DNS_BLACKLIST, timeout=2)))
AttributeErrorAttributeError  File "proxy.py", line 781, in dns_remote_resolve
    except gevent.timeout.Timeout as e:
Unhandled exception in thread started by <function do_remote_resolve at 0x10c6fab18>
Traceback (most recent call last):
  File "proxy.py", line 1420, in do_remote_resolve
    queue.put((host, dnsservers, dns_remote_resolve(host, dnsservers, self.DNS_BLACKLIST, timeout=2)))
Unhandled exception in thread started by <function do_remote_resolve at 0x10c6fab18>
Traceback (most recent call last):
: 'NoneType' object has no attribute 'timeout'
  File "proxy.py", line 781, in dns_remote_resolve
    except gevent.timeout.Timeout as e:
    except gevent.timeout.Timeout as e:
: AttributeError:     queue.put((host, dnsservers, dns_remote_resolve(host, dnsservers, self.DNS_BLACKLIST, timeout=2)))
Unhandled exception in thread started by <function do_remote_resolve at 0x10c6fab18>
Traceback (most recent call last):
  File "proxy.py", line 1420, in do_remote_resolve
    queue.put((host, dnsservers, dns_remote_resolve(host, dnsservers, self.DNS_BLACKLIST, timeout=2)))
  File "proxy.py", line 781, in dns_remote_resolve
    queue.put((host, dnsservers, dns_remote_resolve(host, dnsservers, self.DNS_BLACKLIST, timeout=2)))
: AttributeError: AttributeError:     queue.put((host, dnsservers, dns_remote_resolve(host, dnsservers, self.DNS_BLACKLIST, timeout=2)))
  File "proxy.py", line 781, in dns_remote_resolve
    except gevent.timeout.Timeout as e:
  File "proxy.py", line 781, in dns_remote_resolve
    except gevent.timeout.Timeout as e:
  File "proxy.py", line 1420, in do_remote_resolve
  File "proxy.py", line 781, in dns_remote_resolve
    except gevent.timeout.Timeout as e:
AttributeError: 'NoneType' object has no attribute 'timeout': 'NoneType' object has no attribute 'timeout''NoneType' object has no attribute 'timeout'
  File "proxy.py", line 781, in dns_remote_resolve
AttributeError: 'NoneType' object has no attribute 'timeout'AttributeError    queue.put((host, dnsservers, dns_remote_resolve(host, dnsservers, self.DNS_BLACKLIST, timeout=2)))
    except gevent.timeout.Timeout as e:
AttributeError: 'NoneType' object has no attribute 'timeout''NoneType' object has no attribute 'timeout''NoneType' object has no attribute 'timeout'

    'NoneType' object has no attribute 'timeout'

:     except gevent.timeout.Timeout as e:
AttributeError: 
'NoneType' object has no attribute 'timeout'
'NoneType' object has no attribute 'timeout'
except gevent.timeout.Timeout as e:
AttributeError'NoneType' object has no attribute 'timeout'
'NoneType' object has no attribute 'timeout'

AttributeError:   File "proxy.py", line 781, in dns_remote_resolve
  File "proxy.py", line 781, in dns_remote_resolve
    except gevent.timeout.Timeout as e:

: 'NoneType' object has no attribute 'timeout'
    except gevent.timeout.Timeout as e:
AttributeError: 'NoneType' object has no attribute 'timeout'
AttributeError: 'NoneType' object has no attribute 'timeout'  File "proxy.py", line 781, in dns_remote_resolve
    except gevent.timeout.Timeout as e:
'NoneType' object has no attribute 'timeout'

'NoneType' object has no attribute 'timeout'AttributeError: 'NoneType' object has no attribute 'timeout'

WARNING - [Jan 25 15:25:59] resolve remote timeout, continue
ERROR - [Jan 25 15:25:59] resolve google_hk host return empty! please retry!
Traceback (most recent call last):
  File "/System/Library/Frameworks/Python.framework/Versions/2.7/lib/python2.7/SocketServer.py", line 593, in process_request_thread
    self.finish_request(request, client_address)
  File "proxy.py", line 1828, in finish_request
    self.RequestHandlerClass(request, client_address, self)
  File "/System/Library/Frameworks/Python.framework/Versions/2.7/lib/python2.7/SocketServer.py", line 647, in __init__
    self.setup()
  File "proxy.py", line 1916, in setup
    self.first_run()
  File "proxy.py", line 1901, in first_run
    common.resolve_iplist()
  File "proxy.py", line 1452, in resolve_iplist
    sys.exit(-1)
SystemExit: -1
